<mujoco model="overseas_65_b_v_description">
  <compiler meshdir="../meshes" discardvisual="false" balanceinertia="true" fusestatic="false" angle="radian"/>

  <asset>
    <texture name="skybox" type="skybox" builtin="gradient" rgb1=".4 .6 .8" rgb2="0 0 0" 
             width="800" height="800" mark="random" markrgb="1 1 1"/>
    
    <texture name="grid" type="2d" builtin="checker" width="512" height="512" 
             rgb1=".1 .2 .3" rgb2=".2 .3 .4"/>
    
    <material name="grid" texture="grid" texrepeat="1 1" texuniform="true" reflectance=".2"/>

    <mesh name="base_link_underpan" content_type="model/stl" file="base_link_underpan.STL"/>
    <mesh name="link_right_wheel" content_type="model/stl" file="link_right_wheel.STL"/>
    <mesh name="link_left_wheel" content_type="model/stl" file="link_left_wheel.STL"/>
    <mesh name="link_swivel_wheel_1_1" content_type="model/stl" file="link_swivel_wheel_1_1.STL"/>
    <mesh name="link_swivel_wheel_1_2" content_type="model/stl" file="link_swivel_wheel_1_2.STL"/>
    <mesh name="link_swivel_wheel_2_1" content_type="model/stl" file="link_swivel_wheel_2_1.STL"/>
    <mesh name="link_swivel_wheel_2_2" content_type="model/stl" file="link_swivel_wheel_2_2.STL"/>
    <mesh name="link_swivel_wheel_3_1" content_type="model/stl" file="link_swivel_wheel_3_1.STL"/>
    <mesh name="link_swivel_wheel_3_2" content_type="model/stl" file="link_swivel_wheel_3_2.STL"/>
    <mesh name="link_swivel_wheel_4_1" content_type="model/stl" file="link_swivel_wheel_4_1.STL"/>
    <mesh name="link_swivel_wheel_4_2" content_type="model/stl" file="link_swivel_wheel_4_2.STL"/>
    <mesh name="body_base_link" content_type="model/stl" file="body_base_link.STL"/>
    <mesh name="platform_base_link" content_type="model/stl" file="platform_base_link.STL"/>
    <mesh name="head_link1" content_type="model/stl" file="head_link1.STL"/>
    <mesh name="head_link2" content_type="model/stl" file="head_link2.STL"/>
    <mesh name="camera_link" content_type="model/stl" file="camera_link.STL"/>
    <mesh name="l_base_link1" content_type="model/stl" file="l_base_link1.STL"/>
    <mesh name="r_base_link1" content_type="model/stl" file="r_base_link1.STL"/>
    <mesh name="r_link1" content_type="model/stl" file="r_link1.STL"/>
    <mesh name="r_link2" content_type="model/stl" file="r_link2.STL"/>
    <mesh name="r_link3" content_type="model/stl" file="r_link3.STL"/>
    <mesh name="r_link4" content_type="model/stl" file="r_link4.STL"/>
    <mesh name="r_link5" content_type="model/stl" file="r_link5.STL"/>
    <mesh name="r_link6" content_type="model/stl" file="r_link6.STL"/>
    <mesh name="r_hand_base_link" content_type="model/stl" file="r_hand_base_link.STL"/>
    <mesh name="l_link1" content_type="model/stl" file="l_link1.STL"/>
    <mesh name="l_link2" content_type="model/stl" file="l_link2.STL"/>
    <mesh name="l_link3" content_type="model/stl" file="l_link3.STL"/>
    <mesh name="l_link4" content_type="model/stl" file="l_link4.STL"/>
    <mesh name="l_link5" content_type="model/stl" file="l_link5.STL"/>
    <mesh name="l_link6" content_type="model/stl" file="l_link6.STL"/>
    <mesh name="l_hand_base_link" content_type="model/stl" file="l_hand_base_link.STL"/>
  </asset>

  <worldbody>
    <light name="sun" directional="true" pos="-1 -1 3" dir="0.3 0.3 -1" castshadow="true" 
           diffuse=".7 .7 .7" specular=".3 .3 .3"/>
           
    <geom name="floor" type="plane" pos="0 0 0" size="0 0 .05" material="grid" condim="3"/>

    <geom type="mesh" contype="0" conaffinity="0" group="1" density="0" rgba="0.79216 0.81961 0.93333 1" mesh="base_link_underpan"/>
    <geom type="mesh" rgba="0.79216 0.81961 0.93333 1" mesh="base_link_underpan"/>
    <geom type="mesh" contype="0" conaffinity="0" group="1" density="0" rgba="0.79216 0.81961 0.93333 1" mesh="body_base_link"/>
    <geom type="mesh" contype="0" conaffinity="0" rgba="0.79216 0.81961 0.93333 1" mesh="body_base_link"/>
    <body name="platform_base_link" pos="0 -0.11663 0.337">
      <inertial pos="0.0153361 -0.0500754 0.00403219" quat="0.516458 0.462527 0.474746 0.542177" mass="3.36802" diaginertia="0.0426843 0.0275199 0.0187536"/>
      <joint name="platform_joint" pos="0 0 0" axis="0 0 1" type="slide" range="-0.01 0.82" actuatorfrcrange="-600 600"/>
      <geom type="mesh" contype="0" conaffinity="0" group="1" density="0" rgba="0.79216 0.81961 0.93333 1" mesh="platform_base_link"/>
      <geom type="mesh" contype="0" conaffinity="0" rgba="0.79216 0.81961 0.93333 1" mesh="platform_base_link"/>
      <geom pos="0.1 -0.1103 0.031645" quat="4.28004e-05 0.382684 -1.77285e-05 0.923879" type="mesh" contype="0" conaffinity="0" group="1" density="0" rgba="0.79216 0.81961 0.93333 1" mesh="l_base_link1"/>
      <geom pos="0.1 -0.1103 0.031645" quat="4.28004e-05 0.382684 -1.77285e-05 0.923879" type="mesh" rgba="0.79216 0.81961 0.93333 1" mesh="l_base_link1"/>
      <geom pos="-0.1 -0.1103 0.031645" quat="0.923879 0 -0.382684 0" type="mesh" contype="0" conaffinity="0" group="1" density="0" rgba="0.79216 0.81961 0.93333 1" mesh="r_base_link1"/>
      <geom pos="-0.1 -0.1103 0.031645" quat="0.923879 0 -0.382684 0" type="mesh" rgba="0.79216 0.81961 0.93333 1" mesh="r_base_link1"/>
      <body name="head_link1" pos="0 -0.1018 0.126">
        <inertial pos="-0.00017562 -0.015989 0.024926" quat="0.70598 -0.0294127 0.00889767 0.707565" mass="0.049513" diaginertia="2.21963e-05 1.62532e-05 1.35775e-05"/>
        <joint name="head_joint1" pos="0 0 0" axis="0 0 1" range="-1.256 1.256" actuatorfrcrange="-2 2" damping="0.5" />
        <geom type="mesh" contype="0" conaffinity="0" group="1" density="0" rgba="0.79216 0.81961 0.93333 1" mesh="head_link1"/>
        <geom type="mesh" rgba="0.79216 0.81961 0.93333 1" mesh="head_link1"/>
        <body name="head_link2" pos="0 -0.02 0.044">
          <inertial pos="0.0107298 -0.0157618 0.0449146" quat="0.0629225 0.691414 0.473763 0.541789" mass="0.286168" diaginertia="0.00108105 0.000898425 0.000409092"/>
          <joint name="head_joint2" pos="0 0 0" axis="-1 0 0" range="-0.419 0.419" actuatorfrcrange="-2 2" damping="0.5"/>
          <geom type="mesh" contype="0" conaffinity="0" group="1" density="0" rgba="0.79216 0.81961 0.93333 1" mesh="head_link2"/>
          <geom type="mesh" rgba="0.79216 0.81961 0.93333 1" mesh="head_link2"/>
          <geom pos="-0.0032391 -0.051866 0.061606" quat="1 0 0 0" type="mesh" contype="0" conaffinity="0" group="1" density="0" rgba="0.79216 0.81961 0.93333 1" mesh="camera_link"/>
          <geom pos="-0.0032391 -0.051866 0.061606" quat="1 0 0 0" type="mesh" rgba="0.79216 0.81961 0.93333 1" mesh="camera_link"/>
        </body>
      </body>
      <body name="l_link1" pos="0.232229 -0.110312 0.163874" quat="-0.923879 0 -0.382684 8.56007e-05">
        <inertial pos="-2.9675e-07 0.021107 -0.025188" quat="0.988853 -0.148894 -1.495e-05 -0.000114968" mass="0.59353" diaginertia="0.0012661 0.00124667 0.000496239"/>
        <joint name="l_joint1" pos="0 0 0" axis="0 0 1" range="-3.11 3.11" actuatorfrcrange="-60 60" damping="5.0"  armature="0.2"/>
        <geom type="mesh" contype="0" conaffinity="0" group="1" density="0" rgba="0.79216 0.81961 0.93333 1" mesh="l_link1"/>
        <geom type="mesh" rgba="0.79216 0.81961 0.93333 1" mesh="l_link1"/>
        <body name="l_link2" quat="0.499998 0.5 -0.5 0.500002">
          <inertial pos="0.15226 2.3916e-07 -0.0062027" quat="5.16616e-05 0.800119 6.89106e-05 0.599841" mass="0.86416" diaginertia="0.00207595 0.0020527 0.000509376"/>
          <joint name="l_joint2" pos="0 0 0" axis="0 0 1" range="-2.27 2.27" actuatorfrcrange="-60 60" damping="5.0" armature="0.2"/>
          <geom type="mesh" contype="0" conaffinity="0" group="1" density="0" rgba="0.79216 0.81961 0.93333 1" mesh="l_link2"/>
          <geom type="mesh" rgba="0.79216 0.81961 0.93333 1" mesh="l_link2"/>
          <body name="l_link3" pos="0.256 0 0" quat="0.707105 0 0 0.707108">
            <inertial pos="4.7194e-06 -0.059592 0.010268" quat="0.424687 0.564983 -0.565532 0.424981" mass="0.28963" diaginertia="0.000656042 0.00063737 0.000114628"/>
            <joint name="l_joint3" pos="0 0 0" axis="0 0 1" range="-2.36 2.36" actuatorfrcrange="-30 30" damping="2.0"  armature="0.1"/>
            <geom type="mesh" contype="0" conaffinity="0" group="1" density="0" rgba="0.79216 0.81961 0.93333 1" mesh="l_link3"/>
            <geom type="mesh" rgba="0.79216 0.81961 0.93333 1" mesh="l_link3"/>
            <body name="l_link4" pos="0 -0.21 -0.00030007" quat="0.707105 0.707108 0 0">
              <inertial pos="2.9186e-07 -0.018042 -0.02154" quat="0.990403 0.138211 6.75064e-06 -8.85845e-05" mass="0.23942" diaginertia="0.00028595 0.000275323 0.000107307"/>
              <joint name="l_joint4" pos="0 0 0" axis="0 0 1" range="-3.11 3.11" actuatorfrcrange="-10 10" damping="0.5" armature="0.1"/>
              <geom type="mesh" contype="0" conaffinity="0" group="1" density="0" rgba="0.79216 0.81961 0.93333 1" mesh="l_link4"/>
              <geom type="mesh" rgba="0.79216 0.81961 0.93333 1" mesh="l_link4"/>
              <body name="l_link5" quat="0.707105 -0.707108 0 0">
                <inertial pos="4.2301e-06 -0.059381 0.0070671" quat="0.419742 0.568638 -0.56922 0.420067" mass="0.21879" diaginertia="0.000358601 0.00035053 8.07893e-05"/>
                <joint name="l_joint5" pos="0 0 0" axis="0 0 1" range="-2.23 2.23" actuatorfrcrange="-10 10" damping="0.5" armature="0.01"/>
                <geom type="mesh" contype="0" conaffinity="0" group="1" density="0" rgba="0.79216 0.81961 0.93333 1" mesh="l_link5"/>
                <geom type="mesh" rgba="0.79216 0.81961 0.93333 1" mesh="l_link5"/>
                <body name="l_link6" pos="0 -0.115 -0.00029971" quat="0.707105 -0.707108 0 0">
                  <inertial pos="0.014341 -0.00318695 0.0734523" quat="0.61388 -0.0834037 -0.10374 0.778096" mass="0.41281" diaginertia="0.00201204 0.00181453 0.000560555"/>
                  <joint name="l_joint6" pos="0 0 0" axis="0 0 1" range="-6.28 6.28" actuatorfrcrange="-10 10" damping="0.5" armature="0.01"/>
                  <geom type="mesh" contype="0" conaffinity="0" group="1" density="0" rgba="0.79216 0.81961 0.93333 1" mesh="l_link6"/>
                  <geom type="mesh" rgba="0.79216 0.81961 0.93333 1" mesh="l_link6"/>
                  <geom pos="0 0 0.0445" quat="2.14617e-09 -1 4.63268e-05 4.63268e-05" type="mesh" contype="0" conaffinity="0" group="1" density="0" rgba="0.75294 0.75294 0.75294 1" mesh="l_hand_base_link"/>
                  <geom pos="0 0 0.0445" quat="2.14617e-09 -1 4.63268e-05 4.63268e-05" type="mesh" rgba="0.75294 0.75294 0.75294 1" mesh="l_hand_base_link"/>
                </body>
              </body>
            </body>
          </body>
        </body>
      </body>
      <body name="r_link1" pos="-0.232229 -0.1103 0.163874" quat="0.923879 0 -0.382684 0">
        <inertial pos="-2.8998e-07 0.021107 -0.025188" quat="0.988853 -0.148894 -1.50204e-05 -0.000115167" mass="0.59353" diaginertia="0.0012661 0.00124667 0.000496239"/>
        <joint name="r_joint1" pos="0 0 0" axis="0 0 1" range="-3.11 3.11" actuatorfrcrange="-60 60" damping="5.0" armature="0.2"/>
        <geom type="mesh" contype="0" conaffinity="0" group="1" density="0" rgba="0.79216 0.81961 0.93333 1" mesh="r_link1"/>
        <geom type="mesh" rgba="0.79216 0.81961 0.93333 1" mesh="r_link1"/>
        <body name="r_link2" quat="0.499998 0.5 -0.5 0.500002">
          <inertial pos="0.15226 2.505e-07 -0.0062027" quat="5.13026e-05 0.800119 6.84318e-05 0.599841" mass="0.86416" diaginertia="0.00207595 0.0020527 0.000509376"/>
          <joint name="r_joint2" pos="0 0 0" axis="0 0 1" range="-2.27 2.27" actuatorfrcrange="-60 60" damping="5.0" armature="0.2"/>
          <geom type="mesh" contype="0" conaffinity="0" group="1" density="0" rgba="0.79216 0.81961 0.93333 1" mesh="r_link2"/>
          <geom type="mesh" rgba="0.79216 0.81961 0.93333 1" mesh="r_link2"/>
          <body name="r_link3" pos="0.256 0 0" quat="0.707105 0 0 0.707108">
            <inertial pos="4.7421e-06 -0.059592 0.010268" quat="0.424687 0.564983 -0.565532 0.424981" mass="0.28963" diaginertia="0.000656042 0.00063737 0.000114628"/>
            <joint name="r_joint3" pos="0 0 0" axis="0 0 1" range="-2.36 2.36" actuatorfrcrange="-30 30" damping="2.0" armature="0.1"/>
            <geom type="mesh" contype="0" conaffinity="0" group="1" density="0" rgba="0.79216 0.81961 0.93333 1" mesh="r_link3"/>
            <geom type="mesh" rgba="0.79216 0.81961 0.93333 1" mesh="r_link3"/>
            <body name="r_link4" pos="0 -0.21 -0.00030007" quat="0.707105 0.707108 0 0">
              <inertial pos="2.9088e-07 -0.018042 -0.02154" quat="0.990403 0.138211 6.77379e-06 -8.85868e-05" mass="0.23942" diaginertia="0.00028595 0.000275323 0.000107307"/>
              <joint name="r_joint4" pos="0 0 0" axis="0 0 1" range="-3.11 3.11" actuatorfrcrange="-10 10" damping="0.5" armature="0.1"/>
              <geom type="mesh" contype="0" conaffinity="0" group="1" density="0" rgba="0.79216 0.81961 0.93333 1" mesh="r_link4"/>
              <geom type="mesh" rgba="0.79216 0.81961 0.93333 1" mesh="r_link4"/>
              <body name="r_link5" quat="0.707105 -0.707108 0 0">
                <inertial pos="4.2478e-06 -0.059381 0.007067" quat="0.419746 0.568643 -0.569214 0.420063" mass="0.21879" diaginertia="0.000358601 0.00035053 8.07893e-05"/>
                <joint name="r_joint5" pos="0 0 0" axis="0 0 1" range="-2.23 2.23" actuatorfrcrange="-10 10" damping="0.5" armature="0.01"/>
                <geom type="mesh" contype="0" conaffinity="0" group="1" density="0" rgba="0.79216 0.81961 0.93333 1" mesh="r_link5"/>
                <geom type="mesh" rgba="0.79216 0.81961 0.93333 1" mesh="r_link5"/>
                <body name="r_link6" pos="0 -0.11203 -0.00029971" quat="0.707105 0.707108 0 0">
                  <inertial pos="-0.0185755 0.00112221 0.075051" quat="0.666595 0.0644385 0.0743327 0.7389" mass="0.41284" diaginertia="0.00191106 0.00169254 0.000549997"/>
                  <joint name="r_joint6" pos="0 0 0" axis="0 0 1" range="-6.28 6.28" actuatorfrcrange="-10 10" damping="0.5" armature="0.01"/>
                  <geom type="mesh" contype="0" conaffinity="0" group="1" density="0" rgba="0.79216 0.81961 0.93333 1" mesh="r_link6"/>
                  <geom type="mesh" rgba="0.79216 0.81961 0.93333 1" mesh="r_link6"/>
                  <geom pos="0 0 0.0445" quat="1 0 0 0" type="mesh" contype="0" conaffinity="0" group="1" density="0" rgba="0.75294 0.75294 0.75294 1" mesh="r_hand_base_link"/>
                  <geom pos="0 0 0.0445" quat="1 0 0 0" type="mesh" rgba="0.75294 0.75294 0.75294 1" mesh="r_hand_base_link"/>
                </body>
              </body>
            </body>
          </body>
        </body>
      </body>
    </body>
  </worldbody>





</mujoco>
